<?xml version="1.0"?>
<robot xmlns:xacro="http://www.ros.org/wiki/xacro" name="pilsbot">
  <xacro:property name="frame_length" value="0.94"/>
  <xacro:property name="frame_width" value="0.49"/>
  <xacro:property name="framebar_radius" value="0.01"/>
  <xacro:property name="wheel_radius" value="0.125"/>
  <xacro:property name="front_wheel_length" value="0.05"/>
  <xacro:property name="rear_wheel_length" value="0.08"/>
  
  <xacro:macro name="front_wheel" params="suffix axle_offset">
    <link name="front_wheel_${suffix}">
      <inertial>
        <origin xyz="0.0 0.0 0.0" rpy="0.0 1.57 1.57"/>
        <mass value="1.0"/>
        <inertia ixx="1.0" ixy="0.0" ixz="0.0" iyy="1.0" iyz="0.0" izz="1.0"/>
      </inertial>
      <visual name="">
        <origin xyz="0.0 0.0 0.0" rpy="0.0 1.57 1.57"/>
        <geometry>
          <cylinder radius="${wheel_radius}" length="${front_wheel_length}"/>
        </geometry>
        <material name="black">
          <color rgba="0.0 0.0 0.0 1.0"/>
        </material>
      </visual>
      <collision>
        <origin xyz="0.0 0.0 0.0" rpy="0.0 1.57 1.57"/>
        <geometry>
          <cylinder radius="${wheel_radius}" length="${front_wheel_length}"/>
        </geometry>
      </collision>
    </link>  
    <joint name="front_wheel_${suffix}_joint" type="revolute">
      <parent link="front_axle"/>
      <child link="front_wheel_${suffix}"/>
      <axis xyz="0 1 0"/>
      <limit lower="-3.14159" upper="3.14159" velocity="50.0" effort="1000.0"/>
      <origin xyz="0 ${axle_offset} 0" rpy="0 0 0"/>
    </joint>
    <transmission name="front_wheel_${suffix}_trans">
      <type>transmission_interface/SimpleTransmission</type>
      <joint name="front_wheel_${suffix}_joint">
        <hardwareInterface>VelocityJointInterface</hardwareInterface>
      </joint>
      <actuator name="front_wheel_${suffix}_motor">
        <hardwareInterface>VelocityJointInterface</hardwareInterface>
        <mechanicalReduction>1</mechanicalReduction>
      </actuator>
    </transmission>
  </xacro:macro>

  <xacro:macro name="rear_wheel" params="suffix axle_offset">
    <link name="rear_wheel_${suffix}">
      <inertial>
        <origin xyz="0.0 0.0 0.0" rpy="0.0 1.57 1.57"/>
        <mass value="1.0"/>
        <inertia ixx="1.0" ixy="0.0" ixz="0.0" iyy="1.0" iyz="0.0" izz="1.0"/>
      </inertial>
      <visual name="">
        <origin xyz="0.0 0.0 0.0" rpy="0.0 1.57 1.57"/>
        <geometry>
          <cylinder radius="${wheel_radius}" length="${rear_wheel_length}"/>
        </geometry>
        <material name="black">
          <color rgba="0.0 0.0 0.0 1.0"/>
        </material>
      </visual>
      <collision>
        <origin xyz="0.0 0.0 0.0" rpy="0.0 1.57 1.57"/>
        <geometry>
          <cylinder radius="${wheel_radius}" length="${rear_wheel_length}"/>
        </geometry>
      </collision>
    </link>
    <joint name="rear_wheel_${suffix}_joint" type="revolute">
      <parent link="rear_axle"/>
      <child link="rear_wheel_${suffix}"/>
      <axis xyz="0 1 0"/>
      <limit lower="-3.14159" upper="3.14159" velocity="50.0" effort="1000.0"/>
      <origin xyz="0 ${axle_offset} 0" rpy="0 0 0"/>
    </joint>  
  </xacro:macro>

  <xacro:macro name="axle" params="prefix length parent *origin">   
    <link name="${prefix}_axle">
      <inertial>
        <origin xyz="0.0 0.0 0.0" rpy="0.0 1.57 1.57"/>
        <mass value="0.0"/>
        <inertia ixx="0.0" ixy="0.0" ixz="0.0" iyy="0.0" iyz="0.0" izz="0.0"/>
      </inertial>
      <visual name="front_axle_vis">
        <origin xyz="0.0 0.0 0.0" rpy="0.0 1.57 1.57"/>
        <geometry>
          <cylinder radius="${framebar_radius}" length="${length}"/>
        </geometry>
        <material name="">
          <color rgba="1.0 0.0 0.0 1.0"/>
        </material>
      </visual>
      <collision>
        <origin xyz="0.0 0.0 0.0" rpy="0.0 1.57 1.57"/>
        <geometry>
          <cylinder radius="${framebar_radius}" length="${length}"/>
        </geometry>
      </collision>
    </link>
    <joint name="${prefix}_axle_joint" type="fixed">
      <xacro:insert_block name="origin" />
      <parent link="${parent}"/>
      <child link="${prefix}_axle" />
    </joint>
  </xacro:macro>

  <xacro:macro name="frame_bar" params="prefix parent length *origin">
    <link name="${prefix}_frame_bar">
      <inertial>
        <origin xyz="0.0 0.0 0.0" rpy="0.0 1.57 1.57"/>
        <mass value="0.0"/>
        <inertia ixx="0.0" ixy="0.0" ixz="0.0" iyy="0.0" iyz="0.0" izz="0.0"/>
      </inertial>
      <visual name="front_frame_bar_vis">
        <origin xyz="0.0 0.0 0.0" rpy="0.0 1.57 1.57"/>
        <geometry>
          <cylinder radius="${framebar_radius}" length="${length}"/>
        </geometry>
        <material name="">
          <color rgba="1.0 0.0 0.0 1.0"/>
        </material>
      </visual>
      <collision>
        <origin xyz="0.0 0.0 0.0" rpy="0.0 1.57 1.57"/>
        <geometry>
          <cylinder radius="${framebar_radius}" length="${length}"/>
        </geometry>
      </collision>
    </link>
    <joint name="${prefix}_frame_bar_joint" type="fixed">
      <xacro:insert_block name="origin" />
      <parent link="${parent}"/>
      <child link="${prefix}_frame_bar" />
    </joint>
  </xacro:macro>
  
  <xacro:macro name="steering_axle_bar_vis" params="prefix length *origin">
    <visual name="${prefix}_steering_axle_bar">
      <xacro:insert_block name="origin"/>
      <geometry>
        <cylinder radius="${framebar_radius}" length="${length}"/>
      </geometry>
      <material name="">
        <color rgba="1.0 0.0 0.0 1.0"/>
      </material>
    </visual>
  </xacro:macro>

  <link name="base_link"/>

  <xacro:axle prefix="front" length="0.62" parent="base_link">
    <origin xyz="0 0 0.125" rpy="0 0 0"/>
  </xacro:axle>
  <xacro:axle prefix="rear" length="0.5" parent="front_axle">
    <origin xyz="-0.67 0 0" rpy="0 0 0"/>
  </xacro:axle>

  <link name="steering_axle">
    <inertial>
      <origin xyz="0.0 0.0 0.0" rpy="0.0 0.0 0.0"/>
      <mass value="0.0"/>
      <inertia ixx="0.0" ixy="0.0" ixz="0.0" iyy="0.0" iyz="0.0" izz="0.0"/>
    </inertial>
    <visual name="steering_axle">
      <origin xyz="0.0 0.0 0.0" rpy="0.0 0.0 0.0"/>
      <geometry>
        <cylinder radius="0.0275" length="0.1"/>
      </geometry>
      <material name="">
        <color rgba="1.0 0.0 0.0 1.0"/>
        <texture filename=""/>
      </material>
    </visual>
    <xacro:steering_axle_bar_vis prefix="left" length="0.2">
      <origin xyz="0.0 0.1 0.0" rpy="0.0 1.57 1.57"/>
    </xacro:steering_axle_bar_vis>
    <xacro:steering_axle_bar_vis prefix="left_up" length="0.12">
      <origin xyz="0.0 0.23 0.05" rpy="0.0 0.17453 1.57"/>
    </xacro:steering_axle_bar_vis>
    <xacro:steering_axle_bar_vis prefix="right" length="0.2">
      <origin xyz="0.0 -0.1 0.0" rpy="0.0 1.57 1.57"/>
    </xacro:steering_axle_bar_vis>
    <xacro:steering_axle_bar_vis prefix="right_up" length="0.12">
      <origin xyz="0.0 -0.23 0.05" rpy="0.0 -0.17453 1.57"/>
    </xacro:steering_axle_bar_vis>
    <collision>
      <origin xyz="0.0 0.0 0.0" rpy="0.0 0.0 0.0"/>
      <geometry>
        <cylinder radius="0.0275" length="0.1"/>
      </geometry>
    </collision>
  </link>
  
  <joint name="steering_axle_joint" type="revolute">
    <parent link="front_axle"/>
    <child link="steering_axle"/>
    <axis xyz="0 0 1"/>
    <limit lower="-3.14159" upper="3.14159" velocity="50.0" effort="1000.0"/>
    <origin xyz="0 0 0.05" rpy="0 0 0"/>
  </joint>
  
  <xacro:frame_bar prefix="front" parent="steering_axle" length="0.49">
    <origin xyz="0.13 0.0 0.11" rpy="0.0 0.0 0.0"/>
  </xacro:frame_bar>

  <xacro:frame_bar prefix="left" parent="front_frame_bar" length="0.94">
    <origin xyz="-0.47 0.255 0.0" rpy="0.0 0.0 1.57"/>
  </xacro:frame_bar>

  <xacro:frame_bar prefix="right" parent="front_frame_bar" length="0.94">
    <origin xyz="-0.47 -0.255 0.0" rpy="0.0 0.0 1.57"/>
  </xacro:frame_bar>

  <xacro:frame_bar prefix="back" parent="front_frame_bar" length="0.49">
    <origin xyz="-0.94 0.0 0.0" rpy="0.0 0.0 0.0"/>
  </xacro:frame_bar>    
  
  <xacro:front_wheel suffix="left" axle_offset="0.31"/>
  <xacro:front_wheel suffix="right" axle_offset="-0.31"/>
  <xacro:rear_wheel suffix="left" axle_offset="0.27"/>
  <xacro:rear_wheel suffix="right" axle_offset="-0.27"/>
</robot>
